[I 13:11:57.574 NotebookApp] Serving notebooks from local directory: /gpfs/home4/zimmer/neutrino_clustering_V2
[I 13:11:57.574 NotebookApp] Jupyter Notebook 6.4.12 is running at:
[I 13:11:57.574 NotebookApp] http://localhost:5444/?token=e892e0ba923f08fb0ec71af044d8b09fea3273440506de31
[I 13:11:57.574 NotebookApp]  or http://127.0.0.1:5444/?token=e892e0ba923f08fb0ec71af044d8b09fea3273440506de31
[I 13:11:57.574 NotebookApp] Use Control-C to stop this server and shut down all kernels (twice to skip confirmation).
[C 13:11:57.591 NotebookApp] 
    
    To access the notebook, open this file in a browser:
        file:///gpfs/home4/zimmer/.local/share/jupyter/runtime/nbserver-3360122-open.html
    Or copy and paste one of these URLs:
        http://localhost:5444/?token=e892e0ba923f08fb0ec71af044d8b09fea3273440506de31
     or http://127.0.0.1:5444/?token=e892e0ba923f08fb0ec71af044d8b09fea3273440506de31
[I 13:15:12.468 NotebookApp] Creating new notebook in 
[I 13:15:12.586 NotebookApp] Kernel started: 94cd1f5f-b563-449a-ba02-4f508888cef8, name: python3
[W 13:15:12.596 NotebookApp] delete /convergence-jvsc-aad14987-6045-4223-86cf-78596c64e751bef40813-2f53-4586-b045-5bc12939f3ef.ipynb
[W 13:15:12.597 NotebookApp] Skipping trash for /gpfs/home4/zimmer/neutrino_clustering_V2/convergence-jvsc-aad14987-6045-4223-86cf-78596c64e751bef40813-2f53-4586-b045-5bc12939f3ef.ipynb, [Errno 13] Permission denied: b'/gpfs/home4/.Trash-59104'
Traceback (most recent call last):
  File "/home/zimmer/.local/lib/python3.9/site-packages/IPython/core/completer.py", line 2159, in _complete
    for m in matcher(text)])
  File "/home/zimmer/.local/lib/python3.9/site-packages/IPython/core/completer.py", line 1713, in dict_key_matches
    keys = self._get_keys(obj)
  File "/home/zimmer/.local/lib/python3.9/site-packages/IPython/core/completer.py", line 1643, in _get_keys
    return method()
  File "/home/zimmer/.conda/envs/neutrino_clustering/lib/python3.9/site-packages/h5py/_hl/base.py", line 467, in _ipython_key_completions_
    return sorted(self.keys())
  File "/home/zimmer/.conda/envs/neutrino_clustering/lib/python3.9/_collections_abc.py", line 805, in __len__
    return len(self._mapping)
  File "h5py/_objects.pyx", line 54, in h5py._objects.with_phil.wrapper
  File "h5py/_objects.pyx", line 55, in h5py._objects.with_phil.wrapper
  File "/home/zimmer/.conda/envs/neutrino_clustering/lib/python3.9/site-packages/h5py/_hl/group.py", line 466, in __len__
    return self.id.get_num_objs()
  File "h5py/_objects.pyx", line 54, in h5py._objects.with_phil.wrapper
  File "h5py/_objects.pyx", line 55, in h5py._objects.with_phil.wrapper
  File "h5py/h5g.pyx", line 336, in h5py.h5g.GroupID.get_num_objs
ValueError: Invalid group (or file) id (invalid group (or file) ID)
Traceback (most recent call last):
  File "/home/zimmer/.local/lib/python3.9/site-packages/IPython/core/completer.py", line 2159, in _complete
    for m in matcher(text)])
  File "/home/zimmer/.local/lib/python3.9/site-packages/IPython/core/completer.py", line 1713, in dict_key_matches
    keys = self._get_keys(obj)
  File "/home/zimmer/.local/lib/python3.9/site-packages/IPython/core/completer.py", line 1643, in _get_keys
    return method()
  File "/home/zimmer/.conda/envs/neutrino_clustering/lib/python3.9/site-packages/h5py/_hl/base.py", line 467, in _ipython_key_completions_
    return sorted(self.keys())
  File "/home/zimmer/.conda/envs/neutrino_clustering/lib/python3.9/_collections_abc.py", line 805, in __len__
    return len(self._mapping)
  File "h5py/_objects.pyx", line 54, in h5py._objects.with_phil.wrapper
  File "h5py/_objects.pyx", line 55, in h5py._objects.with_phil.wrapper
  File "/home/zimmer/.conda/envs/neutrino_clustering/lib/python3.9/site-packages/h5py/_hl/group.py", line 466, in __len__
    return self.id.get_num_objs()
  File "h5py/_objects.pyx", line 54, in h5py._objects.with_phil.wrapper
  File "h5py/_objects.pyx", line 55, in h5py._objects.with_phil.wrapper
  File "h5py/h5g.pyx", line 336, in h5py.h5g.GroupID.get_num_objs
ValueError: Invalid group (or file) id (invalid group (or file) ID)
Traceback (most recent call last):
  File "/home/zimmer/.local/lib/python3.9/site-packages/IPython/core/completer.py", line 2159, in _complete
    for m in matcher(text)])
  File "/home/zimmer/.local/lib/python3.9/site-packages/IPython/core/completer.py", line 1713, in dict_key_matches
    keys = self._get_keys(obj)
  File "/home/zimmer/.local/lib/python3.9/site-packages/IPython/core/completer.py", line 1643, in _get_keys
    return method()
  File "/home/zimmer/.conda/envs/neutrino_clustering/lib/python3.9/site-packages/h5py/_hl/base.py", line 467, in _ipython_key_completions_
    return sorted(self.keys())
  File "/home/zimmer/.conda/envs/neutrino_clustering/lib/python3.9/_collections_abc.py", line 805, in __len__
    return len(self._mapping)
  File "h5py/_objects.pyx", line 54, in h5py._objects.with_phil.wrapper
  File "h5py/_objects.pyx", line 55, in h5py._objects.with_phil.wrapper
  File "/home/zimmer/.conda/envs/neutrino_clustering/lib/python3.9/site-packages/h5py/_hl/group.py", line 466, in __len__
    return self.id.get_num_objs()
  File "h5py/_objects.pyx", line 54, in h5py._objects.with_phil.wrapper
  File "h5py/_objects.pyx", line 55, in h5py._objects.with_phil.wrapper
  File "h5py/h5g.pyx", line 336, in h5py.h5g.GroupID.get_num_objs
ValueError: Invalid group (or file) id (invalid group (or file) ID)
Traceback (most recent call last):
  File "/home/zimmer/.local/lib/python3.9/site-packages/IPython/core/completer.py", line 2159, in _complete
    for m in matcher(text)])
  File "/home/zimmer/.local/lib/python3.9/site-packages/IPython/core/completer.py", line 1713, in dict_key_matches
    keys = self._get_keys(obj)
  File "/home/zimmer/.local/lib/python3.9/site-packages/IPython/core/completer.py", line 1643, in _get_keys
    return method()
  File "/home/zimmer/.conda/envs/neutrino_clustering/lib/python3.9/site-packages/h5py/_hl/base.py", line 467, in _ipython_key_completions_
    return sorted(self.keys())
  File "/home/zimmer/.conda/envs/neutrino_clustering/lib/python3.9/_collections_abc.py", line 805, in __len__
    return len(self._mapping)
  File "h5py/_objects.pyx", line 54, in h5py._objects.with_phil.wrapper
  File "h5py/_objects.pyx", line 55, in h5py._objects.with_phil.wrapper
  File "/home/zimmer/.conda/envs/neutrino_clustering/lib/python3.9/site-packages/h5py/_hl/group.py", line 466, in __len__
    return self.id.get_num_objs()
  File "h5py/_objects.pyx", line 54, in h5py._objects.with_phil.wrapper
  File "h5py/_objects.pyx", line 55, in h5py._objects.with_phil.wrapper
  File "h5py/h5g.pyx", line 336, in h5py.h5g.GroupID.get_num_objs
ValueError: Invalid group (or file) id (invalid group (or file) ID)
Traceback (most recent call last):
  File "/home/zimmer/.local/lib/python3.9/site-packages/IPython/core/completer.py", line 2159, in _complete
    for m in matcher(text)])
  File "/home/zimmer/.local/lib/python3.9/site-packages/IPython/core/completer.py", line 1713, in dict_key_matches
    keys = self._get_keys(obj)
  File "/home/zimmer/.local/lib/python3.9/site-packages/IPython/core/completer.py", line 1643, in _get_keys
    return method()
  File "/home/zimmer/.conda/envs/neutrino_clustering/lib/python3.9/site-packages/h5py/_hl/base.py", line 467, in _ipython_key_completions_
    return sorted(self.keys())
  File "/home/zimmer/.conda/envs/neutrino_clustering/lib/python3.9/_collections_abc.py", line 805, in __len__
    return len(self._mapping)
  File "h5py/_objects.pyx", line 54, in h5py._objects.with_phil.wrapper
  File "h5py/_objects.pyx", line 55, in h5py._objects.with_phil.wrapper
  File "/home/zimmer/.conda/envs/neutrino_clustering/lib/python3.9/site-packages/h5py/_hl/group.py", line 466, in __len__
    return self.id.get_num_objs()
  File "h5py/_objects.pyx", line 54, in h5py._objects.with_phil.wrapper
  File "h5py/_objects.pyx", line 55, in h5py._objects.with_phil.wrapper
  File "h5py/h5g.pyx", line 336, in h5py.h5g.GroupID.get_num_objs
ValueError: Invalid group (or file) id (invalid group (or file) ID)
Traceback (most recent call last):
  File "/home/zimmer/.local/lib/python3.9/site-packages/IPython/core/completer.py", line 2159, in _complete
    for m in matcher(text)])
  File "/home/zimmer/.local/lib/python3.9/site-packages/IPython/core/completer.py", line 1713, in dict_key_matches
    keys = self._get_keys(obj)
  File "/home/zimmer/.local/lib/python3.9/site-packages/IPython/core/completer.py", line 1643, in _get_keys
    return method()
  File "/home/zimmer/.conda/envs/neutrino_clustering/lib/python3.9/site-packages/h5py/_hl/base.py", line 467, in _ipython_key_completions_
    return sorted(self.keys())
  File "/home/zimmer/.conda/envs/neutrino_clustering/lib/python3.9/_collections_abc.py", line 805, in __len__
    return len(self._mapping)
  File "h5py/_objects.pyx", line 54, in h5py._objects.with_phil.wrapper
  File "h5py/_objects.pyx", line 55, in h5py._objects.with_phil.wrapper
  File "/home/zimmer/.conda/envs/neutrino_clustering/lib/python3.9/site-packages/h5py/_hl/group.py", line 466, in __len__
    return self.id.get_num_objs()
  File "h5py/_objects.pyx", line 54, in h5py._objects.with_phil.wrapper
  File "h5py/_objects.pyx", line 55, in h5py._objects.with_phil.wrapper
  File "h5py/h5g.pyx", line 336, in h5py.h5g.GroupID.get_num_objs
ValueError: Invalid group (or file) id (invalid group (or file) ID)
Traceback (most recent call last):
  File "/home/zimmer/.local/lib/python3.9/site-packages/IPython/core/completer.py", line 2159, in _complete
    for m in matcher(text)])
  File "/home/zimmer/.local/lib/python3.9/site-packages/IPython/core/completer.py", line 1713, in dict_key_matches
    keys = self._get_keys(obj)
  File "/home/zimmer/.local/lib/python3.9/site-packages/IPython/core/completer.py", line 1643, in _get_keys
    return method()
  File "/home/zimmer/.conda/envs/neutrino_clustering/lib/python3.9/site-packages/h5py/_hl/base.py", line 467, in _ipython_key_completions_
    return sorted(self.keys())
  File "/home/zimmer/.conda/envs/neutrino_clustering/lib/python3.9/_collections_abc.py", line 805, in __len__
    return len(self._mapping)
  File "h5py/_objects.pyx", line 54, in h5py._objects.with_phil.wrapper
  File "h5py/_objects.pyx", line 55, in h5py._objects.with_phil.wrapper
  File "/home/zimmer/.conda/envs/neutrino_clustering/lib/python3.9/site-packages/h5py/_hl/group.py", line 466, in __len__
    return self.id.get_num_objs()
  File "h5py/_objects.pyx", line 54, in h5py._objects.with_phil.wrapper
  File "h5py/_objects.pyx", line 55, in h5py._objects.with_phil.wrapper
  File "h5py/h5g.pyx", line 336, in h5py.h5g.GroupID.get_num_objs
ValueError: Invalid group (or file) id (invalid group (or file) ID)
Traceback (most recent call last):
  File "/home/zimmer/.local/lib/python3.9/site-packages/IPython/core/completer.py", line 2159, in _complete
    for m in matcher(text)])
  File "/home/zimmer/.local/lib/python3.9/site-packages/IPython/core/completer.py", line 1713, in dict_key_matches
    keys = self._get_keys(obj)
  File "/home/zimmer/.local/lib/python3.9/site-packages/IPython/core/completer.py", line 1643, in _get_keys
    return method()
  File "/home/zimmer/.conda/envs/neutrino_clustering/lib/python3.9/site-packages/h5py/_hl/base.py", line 467, in _ipython_key_completions_
    return sorted(self.keys())
  File "/home/zimmer/.conda/envs/neutrino_clustering/lib/python3.9/_collections_abc.py", line 805, in __len__
    return len(self._mapping)
  File "h5py/_objects.pyx", line 54, in h5py._objects.with_phil.wrapper
  File "h5py/_objects.pyx", line 55, in h5py._objects.with_phil.wrapper
  File "/home/zimmer/.conda/envs/neutrino_clustering/lib/python3.9/site-packages/h5py/_hl/group.py", line 466, in __len__
    return self.id.get_num_objs()
  File "h5py/_objects.pyx", line 54, in h5py._objects.with_phil.wrapper
  File "h5py/_objects.pyx", line 55, in h5py._objects.with_phil.wrapper
  File "h5py/h5g.pyx", line 336, in h5py.h5g.GroupID.get_num_objs
ValueError: Invalid group (or file) id (invalid group (or file) ID)
Traceback (most recent call last):
  File "/home/zimmer/.local/lib/python3.9/site-packages/IPython/core/completer.py", line 2159, in _complete
    for m in matcher(text)])
  File "/home/zimmer/.local/lib/python3.9/site-packages/IPython/core/completer.py", line 1713, in dict_key_matches
    keys = self._get_keys(obj)
  File "/home/zimmer/.local/lib/python3.9/site-packages/IPython/core/completer.py", line 1643, in _get_keys
    return method()
  File "/home/zimmer/.conda/envs/neutrino_clustering/lib/python3.9/site-packages/h5py/_hl/base.py", line 467, in _ipython_key_completions_
    return sorted(self.keys())
  File "/home/zimmer/.conda/envs/neutrino_clustering/lib/python3.9/_collections_abc.py", line 805, in __len__
    return len(self._mapping)
  File "h5py/_objects.pyx", line 54, in h5py._objects.with_phil.wrapper
  File "h5py/_objects.pyx", line 55, in h5py._objects.with_phil.wrapper
  File "/home/zimmer/.conda/envs/neutrino_clustering/lib/python3.9/site-packages/h5py/_hl/group.py", line 466, in __len__
    return self.id.get_num_objs()
  File "h5py/_objects.pyx", line 54, in h5py._objects.with_phil.wrapper
  File "h5py/_objects.pyx", line 55, in h5py._objects.with_phil.wrapper
  File "h5py/h5g.pyx", line 336, in h5py.h5g.GroupID.get_num_objs
ValueError: Invalid group (or file) id (invalid group (or file) ID)
Traceback (most recent call last):
  File "/home/zimmer/.local/lib/python3.9/site-packages/IPython/core/completer.py", line 2159, in _complete
    for m in matcher(text)])
  File "/home/zimmer/.local/lib/python3.9/site-packages/IPython/core/completer.py", line 1713, in dict_key_matches
    keys = self._get_keys(obj)
  File "/home/zimmer/.local/lib/python3.9/site-packages/IPython/core/completer.py", line 1643, in _get_keys
    return method()
  File "/home/zimmer/.conda/envs/neutrino_clustering/lib/python3.9/site-packages/h5py/_hl/base.py", line 467, in _ipython_key_completions_
    return sorted(self.keys())
  File "/home/zimmer/.conda/envs/neutrino_clustering/lib/python3.9/_collections_abc.py", line 805, in __len__
    return len(self._mapping)
  File "h5py/_objects.pyx", line 54, in h5py._objects.with_phil.wrapper
  File "h5py/_objects.pyx", line 55, in h5py._objects.with_phil.wrapper
  File "/home/zimmer/.conda/envs/neutrino_clustering/lib/python3.9/site-packages/h5py/_hl/group.py", line 466, in __len__
    return self.id.get_num_objs()
  File "h5py/_objects.pyx", line 54, in h5py._objects.with_phil.wrapper
  File "h5py/_objects.pyx", line 55, in h5py._objects.with_phil.wrapper
  File "h5py/h5g.pyx", line 336, in h5py.h5g.GroupID.get_num_objs
ValueError: Invalid group (or file) id (invalid group (or file) ID)
Traceback (most recent call last):
  File "/home/zimmer/.local/lib/python3.9/site-packages/IPython/core/completer.py", line 2159, in _complete
    for m in matcher(text)])
  File "/home/zimmer/.local/lib/python3.9/site-packages/IPython/core/completer.py", line 1713, in dict_key_matches
    keys = self._get_keys(obj)
  File "/home/zimmer/.local/lib/python3.9/site-packages/IPython/core/completer.py", line 1643, in _get_keys
    return method()
  File "/home/zimmer/.conda/envs/neutrino_clustering/lib/python3.9/site-packages/h5py/_hl/base.py", line 467, in _ipython_key_completions_
    return sorted(self.keys())
  File "/home/zimmer/.conda/envs/neutrino_clustering/lib/python3.9/_collections_abc.py", line 805, in __len__
    return len(self._mapping)
  File "h5py/_objects.pyx", line 54, in h5py._objects.with_phil.wrapper
  File "h5py/_objects.pyx", line 55, in h5py._objects.with_phil.wrapper
  File "/home/zimmer/.conda/envs/neutrino_clustering/lib/python3.9/site-packages/h5py/_hl/group.py", line 466, in __len__
    return self.id.get_num_objs()
  File "h5py/_objects.pyx", line 54, in h5py._objects.with_phil.wrapper
  File "h5py/_objects.pyx", line 55, in h5py._objects.with_phil.wrapper
  File "h5py/h5g.pyx", line 336, in h5py.h5g.GroupID.get_num_objs
ValueError: Invalid group (or file) id (invalid group (or file) ID)
Traceback (most recent call last):
  File "/home/zimmer/.local/lib/python3.9/site-packages/IPython/core/completer.py", line 2159, in _complete
    for m in matcher(text)])
  File "/home/zimmer/.local/lib/python3.9/site-packages/IPython/core/completer.py", line 1713, in dict_key_matches
    keys = self._get_keys(obj)
  File "/home/zimmer/.local/lib/python3.9/site-packages/IPython/core/completer.py", line 1643, in _get_keys
    return method()
  File "/home/zimmer/.conda/envs/neutrino_clustering/lib/python3.9/site-packages/h5py/_hl/base.py", line 467, in _ipython_key_completions_
    return sorted(self.keys())
  File "/home/zimmer/.conda/envs/neutrino_clustering/lib/python3.9/_collections_abc.py", line 805, in __len__
    return len(self._mapping)
  File "h5py/_objects.pyx", line 54, in h5py._objects.with_phil.wrapper
  File "h5py/_objects.pyx", line 55, in h5py._objects.with_phil.wrapper
  File "/home/zimmer/.conda/envs/neutrino_clustering/lib/python3.9/site-packages/h5py/_hl/group.py", line 466, in __len__
    return self.id.get_num_objs()
  File "h5py/_objects.pyx", line 54, in h5py._objects.with_phil.wrapper
  File "h5py/_objects.pyx", line 55, in h5py._objects.with_phil.wrapper
  File "h5py/h5g.pyx", line 336, in h5py.h5g.GroupID.get_num_objs
ValueError: Invalid group (or file) id (invalid group (or file) ID)
Traceback (most recent call last):
  File "/home/zimmer/.local/lib/python3.9/site-packages/IPython/core/completer.py", line 2159, in _complete
    for m in matcher(text)])
  File "/home/zimmer/.local/lib/python3.9/site-packages/IPython/core/completer.py", line 1713, in dict_key_matches
    keys = self._get_keys(obj)
  File "/home/zimmer/.local/lib/python3.9/site-packages/IPython/core/completer.py", line 1643, in _get_keys
    return method()
  File "/home/zimmer/.conda/envs/neutrino_clustering/lib/python3.9/site-packages/h5py/_hl/base.py", line 467, in _ipython_key_completions_
    return sorted(self.keys())
  File "/home/zimmer/.conda/envs/neutrino_clustering/lib/python3.9/_collections_abc.py", line 805, in __len__
    return len(self._mapping)
  File "h5py/_objects.pyx", line 54, in h5py._objects.with_phil.wrapper
  File "h5py/_objects.pyx", line 55, in h5py._objects.with_phil.wrapper
  File "/home/zimmer/.conda/envs/neutrino_clustering/lib/python3.9/site-packages/h5py/_hl/group.py", line 466, in __len__
    return self.id.get_num_objs()
  File "h5py/_objects.pyx", line 54, in h5py._objects.with_phil.wrapper
  File "h5py/_objects.pyx", line 55, in h5py._objects.with_phil.wrapper
  File "h5py/h5g.pyx", line 336, in h5py.h5g.GroupID.get_num_objs
ValueError: Invalid group (or file) id (invalid group (or file) ID)
Traceback (most recent call last):
  File "/home/zimmer/.local/lib/python3.9/site-packages/IPython/core/completer.py", line 2159, in _complete
    for m in matcher(text)])
  File "/home/zimmer/.local/lib/python3.9/site-packages/IPython/core/completer.py", line 1713, in dict_key_matches
    keys = self._get_keys(obj)
  File "/home/zimmer/.local/lib/python3.9/site-packages/IPython/core/completer.py", line 1643, in _get_keys
    return method()
  File "/home/zimmer/.conda/envs/neutrino_clustering/lib/python3.9/site-packages/h5py/_hl/base.py", line 467, in _ipython_key_completions_
    return sorted(self.keys())
  File "/home/zimmer/.conda/envs/neutrino_clustering/lib/python3.9/_collections_abc.py", line 805, in __len__
    return len(self._mapping)
  File "h5py/_objects.pyx", line 54, in h5py._objects.with_phil.wrapper
  File "h5py/_objects.pyx", line 55, in h5py._objects.with_phil.wrapper
  File "/home/zimmer/.conda/envs/neutrino_clustering/lib/python3.9/site-packages/h5py/_hl/group.py", line 466, in __len__
    return self.id.get_num_objs()
  File "h5py/_objects.pyx", line 54, in h5py._objects.with_phil.wrapper
  File "h5py/_objects.pyx", line 55, in h5py._objects.with_phil.wrapper
  File "h5py/h5g.pyx", line 336, in h5py.h5g.GroupID.get_num_objs
ValueError: Invalid group (or file) id (invalid group (or file) ID)
Traceback (most recent call last):
  File "/home/zimmer/.local/lib/python3.9/site-packages/IPython/core/completer.py", line 2159, in _complete
    for m in matcher(text)])
  File "/home/zimmer/.local/lib/python3.9/site-packages/IPython/core/completer.py", line 1713, in dict_key_matches
    keys = self._get_keys(obj)
  File "/home/zimmer/.local/lib/python3.9/site-packages/IPython/core/completer.py", line 1643, in _get_keys
    return method()
  File "/home/zimmer/.conda/envs/neutrino_clustering/lib/python3.9/site-packages/h5py/_hl/base.py", line 467, in _ipython_key_completions_
    return sorted(self.keys())
  File "/home/zimmer/.conda/envs/neutrino_clustering/lib/python3.9/_collections_abc.py", line 805, in __len__
    return len(self._mapping)
  File "h5py/_objects.pyx", line 54, in h5py._objects.with_phil.wrapper
  File "h5py/_objects.pyx", line 55, in h5py._objects.with_phil.wrapper
  File "/home/zimmer/.conda/envs/neutrino_clustering/lib/python3.9/site-packages/h5py/_hl/group.py", line 466, in __len__
    return self.id.get_num_objs()
  File "h5py/_objects.pyx", line 54, in h5py._objects.with_phil.wrapper
  File "h5py/_objects.pyx", line 55, in h5py._objects.with_phil.wrapper
  File "h5py/h5g.pyx", line 336, in h5py.h5g.GroupID.get_num_objs
ValueError: Invalid group (or file) id (invalid group (or file) ID)
Traceback (most recent call last):
  File "/home/zimmer/.local/lib/python3.9/site-packages/IPython/core/completer.py", line 2159, in _complete
    for m in matcher(text)])
  File "/home/zimmer/.local/lib/python3.9/site-packages/IPython/core/completer.py", line 1713, in dict_key_matches
    keys = self._get_keys(obj)
  File "/home/zimmer/.local/lib/python3.9/site-packages/IPython/core/completer.py", line 1643, in _get_keys
    return method()
  File "/home/zimmer/.conda/envs/neutrino_clustering/lib/python3.9/site-packages/h5py/_hl/base.py", line 467, in _ipython_key_completions_
    return sorted(self.keys())
  File "/home/zimmer/.conda/envs/neutrino_clustering/lib/python3.9/_collections_abc.py", line 805, in __len__
    return len(self._mapping)
  File "h5py/_objects.pyx", line 54, in h5py._objects.with_phil.wrapper
  File "h5py/_objects.pyx", line 55, in h5py._objects.with_phil.wrapper
  File "/home/zimmer/.conda/envs/neutrino_clustering/lib/python3.9/site-packages/h5py/_hl/group.py", line 466, in __len__
    return self.id.get_num_objs()
  File "h5py/_objects.pyx", line 54, in h5py._objects.with_phil.wrapper
  File "h5py/_objects.pyx", line 55, in h5py._objects.with_phil.wrapper
  File "h5py/h5g.pyx", line 336, in h5py.h5g.GroupID.get_num_objs
ValueError: Invalid group (or file) id (invalid group (or file) ID)
Traceback (most recent call last):
  File "/home/zimmer/.local/lib/python3.9/site-packages/IPython/core/completer.py", line 2159, in _complete
    for m in matcher(text)])
  File "/home/zimmer/.local/lib/python3.9/site-packages/IPython/core/completer.py", line 1713, in dict_key_matches
    keys = self._get_keys(obj)
  File "/home/zimmer/.local/lib/python3.9/site-packages/IPython/core/completer.py", line 1643, in _get_keys
    return method()
  File "/home/zimmer/.conda/envs/neutrino_clustering/lib/python3.9/site-packages/h5py/_hl/base.py", line 467, in _ipython_key_completions_
    return sorted(self.keys())
  File "/home/zimmer/.conda/envs/neutrino_clustering/lib/python3.9/_collections_abc.py", line 805, in __len__
    return len(self._mapping)
  File "h5py/_objects.pyx", line 54, in h5py._objects.with_phil.wrapper
  File "h5py/_objects.pyx", line 55, in h5py._objects.with_phil.wrapper
  File "/home/zimmer/.conda/envs/neutrino_clustering/lib/python3.9/site-packages/h5py/_hl/group.py", line 466, in __len__
    return self.id.get_num_objs()
  File "h5py/_objects.pyx", line 54, in h5py._objects.with_phil.wrapper
  File "h5py/_objects.pyx", line 55, in h5py._objects.with_phil.wrapper
  File "h5py/h5g.pyx", line 336, in h5py.h5g.GroupID.get_num_objs
ValueError: Invalid group (or file) id (invalid group (or file) ID)
Traceback (most recent call last):
  File "/home/zimmer/.local/lib/python3.9/site-packages/IPython/core/completer.py", line 2159, in _complete
    for m in matcher(text)])
  File "/home/zimmer/.local/lib/python3.9/site-packages/IPython/core/completer.py", line 1713, in dict_key_matches
    keys = self._get_keys(obj)
  File "/home/zimmer/.local/lib/python3.9/site-packages/IPython/core/completer.py", line 1643, in _get_keys
    return method()
  File "/home/zimmer/.conda/envs/neutrino_clustering/lib/python3.9/site-packages/h5py/_hl/base.py", line 467, in _ipython_key_completions_
    return sorted(self.keys())
  File "/home/zimmer/.conda/envs/neutrino_clustering/lib/python3.9/_collections_abc.py", line 805, in __len__
    return len(self._mapping)
  File "h5py/_objects.pyx", line 54, in h5py._objects.with_phil.wrapper
  File "h5py/_objects.pyx", line 55, in h5py._objects.with_phil.wrapper
  File "/home/zimmer/.conda/envs/neutrino_clustering/lib/python3.9/site-packages/h5py/_hl/group.py", line 466, in __len__
    return self.id.get_num_objs()
  File "h5py/_objects.pyx", line 54, in h5py._objects.with_phil.wrapper
  File "h5py/_objects.pyx", line 55, in h5py._objects.with_phil.wrapper
  File "h5py/h5g.pyx", line 336, in h5py.h5g.GroupID.get_num_objs
ValueError: Invalid group (or file) id (invalid group (or file) ID)
Traceback (most recent call last):
  File "/home/zimmer/.local/lib/python3.9/site-packages/IPython/core/completer.py", line 2159, in _complete
    for m in matcher(text)])
  File "/home/zimmer/.local/lib/python3.9/site-packages/IPython/core/completer.py", line 1713, in dict_key_matches
    keys = self._get_keys(obj)
  File "/home/zimmer/.local/lib/python3.9/site-packages/IPython/core/completer.py", line 1643, in _get_keys
    return method()
  File "/home/zimmer/.conda/envs/neutrino_clustering/lib/python3.9/site-packages/h5py/_hl/base.py", line 467, in _ipython_key_completions_
    return sorted(self.keys())
  File "/home/zimmer/.conda/envs/neutrino_clustering/lib/python3.9/_collections_abc.py", line 805, in __len__
    return len(self._mapping)
  File "h5py/_objects.pyx", line 54, in h5py._objects.with_phil.wrapper
  File "h5py/_objects.pyx", line 55, in h5py._objects.with_phil.wrapper
  File "/home/zimmer/.conda/envs/neutrino_clustering/lib/python3.9/site-packages/h5py/_hl/group.py", line 466, in __len__
    return self.id.get_num_objs()
  File "h5py/_objects.pyx", line 54, in h5py._objects.with_phil.wrapper
  File "h5py/_objects.pyx", line 55, in h5py._objects.with_phil.wrapper
  File "h5py/h5g.pyx", line 336, in h5py.h5g.GroupID.get_num_objs
ValueError: Invalid group (or file) id (invalid group (or file) ID)
Traceback (most recent call last):
  File "/home/zimmer/.local/lib/python3.9/site-packages/IPython/core/completer.py", line 2159, in _complete
    for m in matcher(text)])
  File "/home/zimmer/.local/lib/python3.9/site-packages/IPython/core/completer.py", line 1713, in dict_key_matches
    keys = self._get_keys(obj)
  File "/home/zimmer/.local/lib/python3.9/site-packages/IPython/core/completer.py", line 1643, in _get_keys
    return method()
  File "/home/zimmer/.conda/envs/neutrino_clustering/lib/python3.9/site-packages/h5py/_hl/base.py", line 467, in _ipython_key_completions_
    return sorted(self.keys())
  File "/home/zimmer/.conda/envs/neutrino_clustering/lib/python3.9/_collections_abc.py", line 805, in __len__
    return len(self._mapping)
  File "h5py/_objects.pyx", line 54, in h5py._objects.with_phil.wrapper
  File "h5py/_objects.pyx", line 55, in h5py._objects.with_phil.wrapper
  File "/home/zimmer/.conda/envs/neutrino_clustering/lib/python3.9/site-packages/h5py/_hl/group.py", line 466, in __len__
    return self.id.get_num_objs()
  File "h5py/_objects.pyx", line 54, in h5py._objects.with_phil.wrapper
  File "h5py/_objects.pyx", line 55, in h5py._objects.with_phil.wrapper
  File "h5py/h5g.pyx", line 336, in h5py.h5g.GroupID.get_num_objs
ValueError: Invalid group (or file) id (invalid group (or file) ID)
Traceback (most recent call last):
  File "/home/zimmer/.local/lib/python3.9/site-packages/IPython/core/completer.py", line 2159, in _complete
    for m in matcher(text)])
  File "/home/zimmer/.local/lib/python3.9/site-packages/IPython/core/completer.py", line 1713, in dict_key_matches
    keys = self._get_keys(obj)
  File "/home/zimmer/.local/lib/python3.9/site-packages/IPython/core/completer.py", line 1643, in _get_keys
    return method()
  File "/home/zimmer/.conda/envs/neutrino_clustering/lib/python3.9/site-packages/h5py/_hl/base.py", line 467, in _ipython_key_completions_
    return sorted(self.keys())
  File "/home/zimmer/.conda/envs/neutrino_clustering/lib/python3.9/_collections_abc.py", line 805, in __len__
    return len(self._mapping)
  File "h5py/_objects.pyx", line 54, in h5py._objects.with_phil.wrapper
  File "h5py/_objects.pyx", line 55, in h5py._objects.with_phil.wrapper
  File "/home/zimmer/.conda/envs/neutrino_clustering/lib/python3.9/site-packages/h5py/_hl/group.py", line 466, in __len__
    return self.id.get_num_objs()
  File "h5py/_objects.pyx", line 54, in h5py._objects.with_phil.wrapper
  File "h5py/_objects.pyx", line 55, in h5py._objects.with_phil.wrapper
  File "h5py/h5g.pyx", line 336, in h5py.h5g.GroupID.get_num_objs
ValueError: Invalid group (or file) id (invalid group (or file) ID)
Traceback (most recent call last):
  File "/home/zimmer/.local/lib/python3.9/site-packages/IPython/core/completer.py", line 2159, in _complete
    for m in matcher(text)])
  File "/home/zimmer/.local/lib/python3.9/site-packages/IPython/core/completer.py", line 1713, in dict_key_matches
    keys = self._get_keys(obj)
  File "/home/zimmer/.local/lib/python3.9/site-packages/IPython/core/completer.py", line 1643, in _get_keys
    return method()
  File "/home/zimmer/.conda/envs/neutrino_clustering/lib/python3.9/site-packages/h5py/_hl/base.py", line 467, in _ipython_key_completions_
    return sorted(self.keys())
  File "/home/zimmer/.conda/envs/neutrino_clustering/lib/python3.9/_collections_abc.py", line 805, in __len__
    return len(self._mapping)
  File "h5py/_objects.pyx", line 54, in h5py._objects.with_phil.wrapper
  File "h5py/_objects.pyx", line 55, in h5py._objects.with_phil.wrapper
  File "/home/zimmer/.conda/envs/neutrino_clustering/lib/python3.9/site-packages/h5py/_hl/attrs.py", line 254, in __len__
    return h5a.get_num_attrs(self._id)
  File "h5py/_objects.pyx", line 54, in h5py._objects.with_phil.wrapper
  File "h5py/_objects.pyx", line 55, in h5py._objects.with_phil.wrapper
  File "h5py/h5a.pyx", line 159, in h5py.h5a.get_num_attrs
ValueError: Invalid location identifier (invalid identifier type to function)
Traceback (most recent call last):
  File "/home/zimmer/.local/lib/python3.9/site-packages/IPython/core/completer.py", line 2159, in _complete
    for m in matcher(text)])
  File "/home/zimmer/.local/lib/python3.9/site-packages/IPython/core/completer.py", line 1713, in dict_key_matches
    keys = self._get_keys(obj)
  File "/home/zimmer/.local/lib/python3.9/site-packages/IPython/core/completer.py", line 1643, in _get_keys
    return method()
  File "/home/zimmer/.conda/envs/neutrino_clustering/lib/python3.9/site-packages/h5py/_hl/base.py", line 467, in _ipython_key_completions_
    return sorted(self.keys())
  File "/home/zimmer/.conda/envs/neutrino_clustering/lib/python3.9/_collections_abc.py", line 805, in __len__
    return len(self._mapping)
  File "h5py/_objects.pyx", line 54, in h5py._objects.with_phil.wrapper
  File "h5py/_objects.pyx", line 55, in h5py._objects.with_phil.wrapper
  File "/home/zimmer/.conda/envs/neutrino_clustering/lib/python3.9/site-packages/h5py/_hl/attrs.py", line 254, in __len__
    return h5a.get_num_attrs(self._id)
  File "h5py/_objects.pyx", line 54, in h5py._objects.with_phil.wrapper
  File "h5py/_objects.pyx", line 55, in h5py._objects.with_phil.wrapper
  File "h5py/h5a.pyx", line 159, in h5py.h5a.get_num_attrs
ValueError: Invalid location identifier (invalid identifier type to function)
Traceback (most recent call last):
  File "/home/zimmer/.local/lib/python3.9/site-packages/IPython/core/completer.py", line 2159, in _complete
    for m in matcher(text)])
  File "/home/zimmer/.local/lib/python3.9/site-packages/IPython/core/completer.py", line 1713, in dict_key_matches
    keys = self._get_keys(obj)
  File "/home/zimmer/.local/lib/python3.9/site-packages/IPython/core/completer.py", line 1643, in _get_keys
    return method()
  File "/home/zimmer/.conda/envs/neutrino_clustering/lib/python3.9/site-packages/h5py/_hl/base.py", line 467, in _ipython_key_completions_
    return sorted(self.keys())
  File "/home/zimmer/.conda/envs/neutrino_clustering/lib/python3.9/_collections_abc.py", line 805, in __len__
    return len(self._mapping)
  File "h5py/_objects.pyx", line 54, in h5py._objects.with_phil.wrapper
  File "h5py/_objects.pyx", line 55, in h5py._objects.with_phil.wrapper
  File "/home/zimmer/.conda/envs/neutrino_clustering/lib/python3.9/site-packages/h5py/_hl/attrs.py", line 254, in __len__
    return h5a.get_num_attrs(self._id)
  File "h5py/_objects.pyx", line 54, in h5py._objects.with_phil.wrapper
  File "h5py/_objects.pyx", line 55, in h5py._objects.with_phil.wrapper
  File "h5py/h5a.pyx", line 159, in h5py.h5a.get_num_attrs
ValueError: Invalid location identifier (invalid identifier type to function)
Traceback (most recent call last):
  File "/home/zimmer/.local/lib/python3.9/site-packages/IPython/core/completer.py", line 2159, in _complete
    for m in matcher(text)])
  File "/home/zimmer/.local/lib/python3.9/site-packages/IPython/core/completer.py", line 1713, in dict_key_matches
    keys = self._get_keys(obj)
  File "/home/zimmer/.local/lib/python3.9/site-packages/IPython/core/completer.py", line 1643, in _get_keys
    return method()
  File "/home/zimmer/.conda/envs/neutrino_clustering/lib/python3.9/site-packages/h5py/_hl/base.py", line 467, in _ipython_key_completions_
    return sorted(self.keys())
  File "/home/zimmer/.conda/envs/neutrino_clustering/lib/python3.9/_collections_abc.py", line 805, in __len__
    return len(self._mapping)
  File "h5py/_objects.pyx", line 54, in h5py._objects.with_phil.wrapper
  File "h5py/_objects.pyx", line 55, in h5py._objects.with_phil.wrapper
  File "/home/zimmer/.conda/envs/neutrino_clustering/lib/python3.9/site-packages/h5py/_hl/attrs.py", line 254, in __len__
    return h5a.get_num_attrs(self._id)
  File "h5py/_objects.pyx", line 54, in h5py._objects.with_phil.wrapper
  File "h5py/_objects.pyx", line 55, in h5py._objects.with_phil.wrapper
  File "h5py/h5a.pyx", line 159, in h5py.h5a.get_num_attrs
ValueError: Invalid location identifier (invalid identifier type to function)
Traceback (most recent call last):
  File "/home/zimmer/.local/lib/python3.9/site-packages/IPython/core/completer.py", line 2159, in _complete
    for m in matcher(text)])
  File "/home/zimmer/.local/lib/python3.9/site-packages/IPython/core/completer.py", line 1713, in dict_key_matches
    keys = self._get_keys(obj)
  File "/home/zimmer/.local/lib/python3.9/site-packages/IPython/core/completer.py", line 1643, in _get_keys
    return method()
  File "/home/zimmer/.conda/envs/neutrino_clustering/lib/python3.9/site-packages/h5py/_hl/base.py", line 467, in _ipython_key_completions_
    return sorted(self.keys())
  File "/home/zimmer/.conda/envs/neutrino_clustering/lib/python3.9/_collections_abc.py", line 805, in __len__
    return len(self._mapping)
  File "h5py/_objects.pyx", line 54, in h5py._objects.with_phil.wrapper
  File "h5py/_objects.pyx", line 55, in h5py._objects.with_phil.wrapper
  File "/home/zimmer/.conda/envs/neutrino_clustering/lib/python3.9/site-packages/h5py/_hl/attrs.py", line 254, in __len__
    return h5a.get_num_attrs(self._id)
  File "h5py/_objects.pyx", line 54, in h5py._objects.with_phil.wrapper
  File "h5py/_objects.pyx", line 55, in h5py._objects.with_phil.wrapper
  File "h5py/h5a.pyx", line 159, in h5py.h5a.get_num_attrs
ValueError: Invalid location identifier (invalid identifier type to function)
Traceback (most recent call last):
  File "/home/zimmer/.local/lib/python3.9/site-packages/IPython/core/completer.py", line 2159, in _complete
    for m in matcher(text)])
  File "/home/zimmer/.local/lib/python3.9/site-packages/IPython/core/completer.py", line 1713, in dict_key_matches
    keys = self._get_keys(obj)
  File "/home/zimmer/.local/lib/python3.9/site-packages/IPython/core/completer.py", line 1643, in _get_keys
    return method()
  File "/home/zimmer/.conda/envs/neutrino_clustering/lib/python3.9/site-packages/h5py/_hl/base.py", line 467, in _ipython_key_completions_
    return sorted(self.keys())
  File "/home/zimmer/.conda/envs/neutrino_clustering/lib/python3.9/_collections_abc.py", line 805, in __len__
    return len(self._mapping)
  File "h5py/_objects.pyx", line 54, in h5py._objects.with_phil.wrapper
  File "h5py/_objects.pyx", line 55, in h5py._objects.with_phil.wrapper
  File "/home/zimmer/.conda/envs/neutrino_clustering/lib/python3.9/site-packages/h5py/_hl/attrs.py", line 254, in __len__
    return h5a.get_num_attrs(self._id)
  File "h5py/_objects.pyx", line 54, in h5py._objects.with_phil.wrapper
  File "h5py/_objects.pyx", line 55, in h5py._objects.with_phil.wrapper
  File "h5py/h5a.pyx", line 159, in h5py.h5a.get_num_attrs
ValueError: Invalid location identifier (invalid identifier type to function)
Traceback (most recent call last):
  File "/home/zimmer/.local/lib/python3.9/site-packages/IPython/core/completer.py", line 2159, in _complete
    for m in matcher(text)])
  File "/home/zimmer/.local/lib/python3.9/site-packages/IPython/core/completer.py", line 1713, in dict_key_matches
    keys = self._get_keys(obj)
  File "/home/zimmer/.local/lib/python3.9/site-packages/IPython/core/completer.py", line 1643, in _get_keys
    return method()
  File "/home/zimmer/.conda/envs/neutrino_clustering/lib/python3.9/site-packages/h5py/_hl/base.py", line 467, in _ipython_key_completions_
    return sorted(self.keys())
  File "/home/zimmer/.conda/envs/neutrino_clustering/lib/python3.9/_collections_abc.py", line 805, in __len__
    return len(self._mapping)
  File "h5py/_objects.pyx", line 54, in h5py._objects.with_phil.wrapper
  File "h5py/_objects.pyx", line 55, in h5py._objects.with_phil.wrapper
  File "/home/zimmer/.conda/envs/neutrino_clustering/lib/python3.9/site-packages/h5py/_hl/attrs.py", line 254, in __len__
    return h5a.get_num_attrs(self._id)
  File "h5py/_objects.pyx", line 54, in h5py._objects.with_phil.wrapper
  File "h5py/_objects.pyx", line 55, in h5py._objects.with_phil.wrapper
  File "h5py/h5a.pyx", line 159, in h5py.h5a.get_num_attrs
ValueError: Invalid location identifier (invalid identifier type to function)
Traceback (most recent call last):
  File "/home/zimmer/.local/lib/python3.9/site-packages/IPython/core/completer.py", line 2159, in _complete
    for m in matcher(text)])
  File "/home/zimmer/.local/lib/python3.9/site-packages/IPython/core/completer.py", line 1713, in dict_key_matches
    keys = self._get_keys(obj)
  File "/home/zimmer/.local/lib/python3.9/site-packages/IPython/core/completer.py", line 1643, in _get_keys
    return method()
  File "/home/zimmer/.conda/envs/neutrino_clustering/lib/python3.9/site-packages/h5py/_hl/base.py", line 467, in _ipython_key_completions_
    return sorted(self.keys())
  File "/home/zimmer/.conda/envs/neutrino_clustering/lib/python3.9/_collections_abc.py", line 805, in __len__
    return len(self._mapping)
  File "h5py/_objects.pyx", line 54, in h5py._objects.with_phil.wrapper
  File "h5py/_objects.pyx", line 55, in h5py._objects.with_phil.wrapper
  File "/home/zimmer/.conda/envs/neutrino_clustering/lib/python3.9/site-packages/h5py/_hl/attrs.py", line 254, in __len__
    return h5a.get_num_attrs(self._id)
  File "h5py/_objects.pyx", line 54, in h5py._objects.with_phil.wrapper
  File "h5py/_objects.pyx", line 55, in h5py._objects.with_phil.wrapper
  File "h5py/h5a.pyx", line 159, in h5py.h5a.get_num_attrs
ValueError: Invalid location identifier (invalid identifier type to function)
Traceback (most recent call last):
  File "/home/zimmer/.local/lib/python3.9/site-packages/IPython/core/completer.py", line 2159, in _complete
    for m in matcher(text)])
  File "/home/zimmer/.local/lib/python3.9/site-packages/IPython/core/completer.py", line 1713, in dict_key_matches
    keys = self._get_keys(obj)
  File "/home/zimmer/.local/lib/python3.9/site-packages/IPython/core/completer.py", line 1643, in _get_keys
    return method()
  File "/home/zimmer/.conda/envs/neutrino_clustering/lib/python3.9/site-packages/h5py/_hl/base.py", line 467, in _ipython_key_completions_
    return sorted(self.keys())
  File "/home/zimmer/.conda/envs/neutrino_clustering/lib/python3.9/_collections_abc.py", line 805, in __len__
    return len(self._mapping)
  File "h5py/_objects.pyx", line 54, in h5py._objects.with_phil.wrapper
  File "h5py/_objects.pyx", line 55, in h5py._objects.with_phil.wrapper
  File "/home/zimmer/.conda/envs/neutrino_clustering/lib/python3.9/site-packages/h5py/_hl/attrs.py", line 254, in __len__
    return h5a.get_num_attrs(self._id)
  File "h5py/_objects.pyx", line 54, in h5py._objects.with_phil.wrapper
  File "h5py/_objects.pyx", line 55, in h5py._objects.with_phil.wrapper
  File "h5py/h5a.pyx", line 159, in h5py.h5a.get_num_attrs
ValueError: Invalid location identifier (invalid identifier type to function)
Traceback (most recent call last):
  File "/home/zimmer/.local/lib/python3.9/site-packages/IPython/core/completer.py", line 2159, in _complete
    for m in matcher(text)])
  File "/home/zimmer/.local/lib/python3.9/site-packages/IPython/core/completer.py", line 1713, in dict_key_matches
    keys = self._get_keys(obj)
  File "/home/zimmer/.local/lib/python3.9/site-packages/IPython/core/completer.py", line 1643, in _get_keys
    return method()
  File "/home/zimmer/.conda/envs/neutrino_clustering/lib/python3.9/site-packages/h5py/_hl/base.py", line 467, in _ipython_key_completions_
    return sorted(self.keys())
  File "/home/zimmer/.conda/envs/neutrino_clustering/lib/python3.9/_collections_abc.py", line 805, in __len__
    return len(self._mapping)
  File "h5py/_objects.pyx", line 54, in h5py._objects.with_phil.wrapper
  File "h5py/_objects.pyx", line 55, in h5py._objects.with_phil.wrapper
  File "/home/zimmer/.conda/envs/neutrino_clustering/lib/python3.9/site-packages/h5py/_hl/attrs.py", line 254, in __len__
    return h5a.get_num_attrs(self._id)
  File "h5py/_objects.pyx", line 54, in h5py._objects.with_phil.wrapper
  File "h5py/_objects.pyx", line 55, in h5py._objects.with_phil.wrapper
  File "h5py/h5a.pyx", line 159, in h5py.h5a.get_num_attrs
ValueError: Invalid location identifier (invalid identifier type to function)
Traceback (most recent call last):
  File "/home/zimmer/.local/lib/python3.9/site-packages/IPython/core/completer.py", line 2159, in _complete
    for m in matcher(text)])
  File "/home/zimmer/.local/lib/python3.9/site-packages/IPython/core/completer.py", line 1713, in dict_key_matches
    keys = self._get_keys(obj)
  File "/home/zimmer/.local/lib/python3.9/site-packages/IPython/core/completer.py", line 1643, in _get_keys
    return method()
  File "/home/zimmer/.conda/envs/neutrino_clustering/lib/python3.9/site-packages/h5py/_hl/base.py", line 467, in _ipython_key_completions_
    return sorted(self.keys())
  File "/home/zimmer/.conda/envs/neutrino_clustering/lib/python3.9/_collections_abc.py", line 805, in __len__
    return len(self._mapping)
  File "h5py/_objects.pyx", line 54, in h5py._objects.with_phil.wrapper
  File "h5py/_objects.pyx", line 55, in h5py._objects.with_phil.wrapper
  File "/home/zimmer/.conda/envs/neutrino_clustering/lib/python3.9/site-packages/h5py/_hl/attrs.py", line 254, in __len__
    return h5a.get_num_attrs(self._id)
  File "h5py/_objects.pyx", line 54, in h5py._objects.with_phil.wrapper
  File "h5py/_objects.pyx", line 55, in h5py._objects.with_phil.wrapper
  File "h5py/h5a.pyx", line 159, in h5py.h5a.get_num_attrs
ValueError: Invalid location identifier (invalid identifier type to function)
Traceback (most recent call last):
  File "/home/zimmer/.local/lib/python3.9/site-packages/IPython/core/completer.py", line 2159, in _complete
    for m in matcher(text)])
  File "/home/zimmer/.local/lib/python3.9/site-packages/IPython/core/completer.py", line 1713, in dict_key_matches
    keys = self._get_keys(obj)
  File "/home/zimmer/.local/lib/python3.9/site-packages/IPython/core/completer.py", line 1643, in _get_keys
    return method()
  File "/home/zimmer/.conda/envs/neutrino_clustering/lib/python3.9/site-packages/h5py/_hl/base.py", line 467, in _ipython_key_completions_
    return sorted(self.keys())
  File "/home/zimmer/.conda/envs/neutrino_clustering/lib/python3.9/_collections_abc.py", line 805, in __len__
    return len(self._mapping)
  File "h5py/_objects.pyx", line 54, in h5py._objects.with_phil.wrapper
  File "h5py/_objects.pyx", line 55, in h5py._objects.with_phil.wrapper
  File "/home/zimmer/.conda/envs/neutrino_clustering/lib/python3.9/site-packages/h5py/_hl/attrs.py", line 254, in __len__
    return h5a.get_num_attrs(self._id)
  File "h5py/_objects.pyx", line 54, in h5py._objects.with_phil.wrapper
  File "h5py/_objects.pyx", line 55, in h5py._objects.with_phil.wrapper
  File "h5py/h5a.pyx", line 159, in h5py.h5a.get_num_attrs
ValueError: Invalid location identifier (invalid identifier type to function)
Traceback (most recent call last):
  File "/home/zimmer/.local/lib/python3.9/site-packages/IPython/core/completer.py", line 2159, in _complete
    for m in matcher(text)])
  File "/home/zimmer/.local/lib/python3.9/site-packages/IPython/core/completer.py", line 1713, in dict_key_matches
    keys = self._get_keys(obj)
  File "/home/zimmer/.local/lib/python3.9/site-packages/IPython/core/completer.py", line 1643, in _get_keys
    return method()
  File "/home/zimmer/.conda/envs/neutrino_clustering/lib/python3.9/site-packages/h5py/_hl/base.py", line 467, in _ipython_key_completions_
    return sorted(self.keys())
  File "/home/zimmer/.conda/envs/neutrino_clustering/lib/python3.9/_collections_abc.py", line 805, in __len__
    return len(self._mapping)
  File "h5py/_objects.pyx", line 54, in h5py._objects.with_phil.wrapper
  File "h5py/_objects.pyx", line 55, in h5py._objects.with_phil.wrapper
  File "/home/zimmer/.conda/envs/neutrino_clustering/lib/python3.9/site-packages/h5py/_hl/attrs.py", line 254, in __len__
    return h5a.get_num_attrs(self._id)
  File "h5py/_objects.pyx", line 54, in h5py._objects.with_phil.wrapper
  File "h5py/_objects.pyx", line 55, in h5py._objects.with_phil.wrapper
  File "h5py/h5a.pyx", line 159, in h5py.h5a.get_num_attrs
ValueError: Invalid location identifier (invalid identifier type to function)
Traceback (most recent call last):
  File "/home/zimmer/.local/lib/python3.9/site-packages/IPython/core/completer.py", line 2159, in _complete
    for m in matcher(text)])
  File "/home/zimmer/.local/lib/python3.9/site-packages/IPython/core/completer.py", line 1713, in dict_key_matches
    keys = self._get_keys(obj)
  File "/home/zimmer/.local/lib/python3.9/site-packages/IPython/core/completer.py", line 1643, in _get_keys
    return method()
  File "/home/zimmer/.conda/envs/neutrino_clustering/lib/python3.9/site-packages/h5py/_hl/base.py", line 467, in _ipython_key_completions_
    return sorted(self.keys())
  File "/home/zimmer/.conda/envs/neutrino_clustering/lib/python3.9/_collections_abc.py", line 805, in __len__
    return len(self._mapping)
  File "h5py/_objects.pyx", line 54, in h5py._objects.with_phil.wrapper
  File "h5py/_objects.pyx", line 55, in h5py._objects.with_phil.wrapper
  File "/home/zimmer/.conda/envs/neutrino_clustering/lib/python3.9/site-packages/h5py/_hl/attrs.py", line 254, in __len__
    return h5a.get_num_attrs(self._id)
  File "h5py/_objects.pyx", line 54, in h5py._objects.with_phil.wrapper
  File "h5py/_objects.pyx", line 55, in h5py._objects.with_phil.wrapper
  File "h5py/h5a.pyx", line 159, in h5py.h5a.get_num_attrs
ValueError: Invalid location identifier (invalid identifier type to function)
Traceback (most recent call last):
  File "/home/zimmer/.local/lib/python3.9/site-packages/IPython/core/completer.py", line 2159, in _complete
    for m in matcher(text)])
  File "/home/zimmer/.local/lib/python3.9/site-packages/IPython/core/completer.py", line 1713, in dict_key_matches
    keys = self._get_keys(obj)
  File "/home/zimmer/.local/lib/python3.9/site-packages/IPython/core/completer.py", line 1643, in _get_keys
    return method()
  File "/home/zimmer/.conda/envs/neutrino_clustering/lib/python3.9/site-packages/h5py/_hl/base.py", line 467, in _ipython_key_completions_
    return sorted(self.keys())
  File "/home/zimmer/.conda/envs/neutrino_clustering/lib/python3.9/_collections_abc.py", line 805, in __len__
    return len(self._mapping)
  File "h5py/_objects.pyx", line 54, in h5py._objects.with_phil.wrapper
  File "h5py/_objects.pyx", line 55, in h5py._objects.with_phil.wrapper
  File "/home/zimmer/.conda/envs/neutrino_clustering/lib/python3.9/site-packages/h5py/_hl/attrs.py", line 254, in __len__
    return h5a.get_num_attrs(self._id)
  File "h5py/_objects.pyx", line 54, in h5py._objects.with_phil.wrapper
  File "h5py/_objects.pyx", line 55, in h5py._objects.with_phil.wrapper
  File "h5py/h5a.pyx", line 159, in h5py.h5a.get_num_attrs
ValueError: Invalid location identifier (invalid identifier type to function)
Traceback (most recent call last):
  File "/home/zimmer/.local/lib/python3.9/site-packages/IPython/core/completer.py", line 2159, in _complete
    for m in matcher(text)])
  File "/home/zimmer/.local/lib/python3.9/site-packages/IPython/core/completer.py", line 1713, in dict_key_matches
    keys = self._get_keys(obj)
  File "/home/zimmer/.local/lib/python3.9/site-packages/IPython/core/completer.py", line 1643, in _get_keys
    return method()
  File "/home/zimmer/.conda/envs/neutrino_clustering/lib/python3.9/site-packages/h5py/_hl/base.py", line 467, in _ipython_key_completions_
    return sorted(self.keys())
  File "/home/zimmer/.conda/envs/neutrino_clustering/lib/python3.9/_collections_abc.py", line 805, in __len__
    return len(self._mapping)
  File "h5py/_objects.pyx", line 54, in h5py._objects.with_phil.wrapper
  File "h5py/_objects.pyx", line 55, in h5py._objects.with_phil.wrapper
  File "/home/zimmer/.conda/envs/neutrino_clustering/lib/python3.9/site-packages/h5py/_hl/attrs.py", line 254, in __len__
    return h5a.get_num_attrs(self._id)
  File "h5py/_objects.pyx", line 54, in h5py._objects.with_phil.wrapper
  File "h5py/_objects.pyx", line 55, in h5py._objects.with_phil.wrapper
  File "h5py/h5a.pyx", line 159, in h5py.h5a.get_num_attrs
ValueError: Invalid location identifier (invalid identifier type to function)
Traceback (most recent call last):
  File "/home/zimmer/.local/lib/python3.9/site-packages/IPython/core/completer.py", line 2159, in _complete
    for m in matcher(text)])
  File "/home/zimmer/.local/lib/python3.9/site-packages/IPython/core/completer.py", line 1713, in dict_key_matches
    keys = self._get_keys(obj)
  File "/home/zimmer/.local/lib/python3.9/site-packages/IPython/core/completer.py", line 1643, in _get_keys
    return method()
  File "/home/zimmer/.conda/envs/neutrino_clustering/lib/python3.9/site-packages/h5py/_hl/base.py", line 467, in _ipython_key_completions_
    return sorted(self.keys())
  File "/home/zimmer/.conda/envs/neutrino_clustering/lib/python3.9/_collections_abc.py", line 805, in __len__
    return len(self._mapping)
  File "h5py/_objects.pyx", line 54, in h5py._objects.with_phil.wrapper
  File "h5py/_objects.pyx", line 55, in h5py._objects.with_phil.wrapper
  File "/home/zimmer/.conda/envs/neutrino_clustering/lib/python3.9/site-packages/h5py/_hl/attrs.py", line 254, in __len__
    return h5a.get_num_attrs(self._id)
  File "h5py/_objects.pyx", line 54, in h5py._objects.with_phil.wrapper
  File "h5py/_objects.pyx", line 55, in h5py._objects.with_phil.wrapper
  File "h5py/h5a.pyx", line 159, in h5py.h5a.get_num_attrs
ValueError: Invalid location identifier (invalid identifier type to function)
Traceback (most recent call last):
  File "/home/zimmer/.local/lib/python3.9/site-packages/IPython/core/completer.py", line 2159, in _complete
    for m in matcher(text)])
  File "/home/zimmer/.local/lib/python3.9/site-packages/IPython/core/completer.py", line 1713, in dict_key_matches
    keys = self._get_keys(obj)
  File "/home/zimmer/.local/lib/python3.9/site-packages/IPython/core/completer.py", line 1643, in _get_keys
    return method()
  File "/home/zimmer/.conda/envs/neutrino_clustering/lib/python3.9/site-packages/h5py/_hl/base.py", line 467, in _ipython_key_completions_
    return sorted(self.keys())
  File "/home/zimmer/.conda/envs/neutrino_clustering/lib/python3.9/_collections_abc.py", line 805, in __len__
    return len(self._mapping)
  File "h5py/_objects.pyx", line 54, in h5py._objects.with_phil.wrapper
  File "h5py/_objects.pyx", line 55, in h5py._objects.with_phil.wrapper
  File "/home/zimmer/.conda/envs/neutrino_clustering/lib/python3.9/site-packages/h5py/_hl/attrs.py", line 254, in __len__
    return h5a.get_num_attrs(self._id)
  File "h5py/_objects.pyx", line 54, in h5py._objects.with_phil.wrapper
  File "h5py/_objects.pyx", line 55, in h5py._objects.with_phil.wrapper
  File "h5py/h5a.pyx", line 159, in h5py.h5a.get_num_attrs
ValueError: Invalid location identifier (invalid identifier type to function)
Traceback (most recent call last):
  File "/home/zimmer/.local/lib/python3.9/site-packages/IPython/core/completer.py", line 2159, in _complete
    for m in matcher(text)])
  File "/home/zimmer/.local/lib/python3.9/site-packages/IPython/core/completer.py", line 1713, in dict_key_matches
    keys = self._get_keys(obj)
  File "/home/zimmer/.local/lib/python3.9/site-packages/IPython/core/completer.py", line 1643, in _get_keys
    return method()
  File "/home/zimmer/.conda/envs/neutrino_clustering/lib/python3.9/site-packages/h5py/_hl/base.py", line 467, in _ipython_key_completions_
    return sorted(self.keys())
  File "/home/zimmer/.conda/envs/neutrino_clustering/lib/python3.9/_collections_abc.py", line 805, in __len__
    return len(self._mapping)
  File "h5py/_objects.pyx", line 54, in h5py._objects.with_phil.wrapper
  File "h5py/_objects.pyx", line 55, in h5py._objects.with_phil.wrapper
  File "/home/zimmer/.conda/envs/neutrino_clustering/lib/python3.9/site-packages/h5py/_hl/attrs.py", line 254, in __len__
    return h5a.get_num_attrs(self._id)
  File "h5py/_objects.pyx", line 54, in h5py._objects.with_phil.wrapper
  File "h5py/_objects.pyx", line 55, in h5py._objects.with_phil.wrapper
  File "h5py/h5a.pyx", line 159, in h5py.h5a.get_num_attrs
ValueError: Invalid location identifier (invalid identifier type to function)
Traceback (most recent call last):
  File "/home/zimmer/.local/lib/python3.9/site-packages/IPython/core/completer.py", line 2159, in _complete
    for m in matcher(text)])
  File "/home/zimmer/.local/lib/python3.9/site-packages/IPython/core/completer.py", line 1713, in dict_key_matches
    keys = self._get_keys(obj)
  File "/home/zimmer/.local/lib/python3.9/site-packages/IPython/core/completer.py", line 1643, in _get_keys
    return method()
  File "/home/zimmer/.conda/envs/neutrino_clustering/lib/python3.9/site-packages/h5py/_hl/base.py", line 467, in _ipython_key_completions_
    return sorted(self.keys())
  File "/home/zimmer/.conda/envs/neutrino_clustering/lib/python3.9/_collections_abc.py", line 805, in __len__
    return len(self._mapping)
  File "h5py/_objects.pyx", line 54, in h5py._objects.with_phil.wrapper
  File "h5py/_objects.pyx", line 55, in h5py._objects.with_phil.wrapper
  File "/home/zimmer/.conda/envs/neutrino_clustering/lib/python3.9/site-packages/h5py/_hl/attrs.py", line 254, in __len__
    return h5a.get_num_attrs(self._id)
  File "h5py/_objects.pyx", line 54, in h5py._objects.with_phil.wrapper
  File "h5py/_objects.pyx", line 55, in h5py._objects.with_phil.wrapper
  File "h5py/h5a.pyx", line 159, in h5py.h5a.get_num_attrs
ValueError: Invalid location identifier (invalid identifier type to function)
Traceback (most recent call last):
  File "/home/zimmer/.local/lib/python3.9/site-packages/IPython/core/completer.py", line 2159, in _complete
    for m in matcher(text)])
  File "/home/zimmer/.local/lib/python3.9/site-packages/IPython/core/completer.py", line 1713, in dict_key_matches
    keys = self._get_keys(obj)
  File "/home/zimmer/.local/lib/python3.9/site-packages/IPython/core/completer.py", line 1643, in _get_keys
    return method()
  File "/home/zimmer/.conda/envs/neutrino_clustering/lib/python3.9/site-packages/h5py/_hl/base.py", line 467, in _ipython_key_completions_
    return sorted(self.keys())
  File "/home/zimmer/.conda/envs/neutrino_clustering/lib/python3.9/_collections_abc.py", line 805, in __len__
    return len(self._mapping)
  File "h5py/_objects.pyx", line 54, in h5py._objects.with_phil.wrapper
  File "h5py/_objects.pyx", line 55, in h5py._objects.with_phil.wrapper
  File "/home/zimmer/.conda/envs/neutrino_clustering/lib/python3.9/site-packages/h5py/_hl/attrs.py", line 254, in __len__
    return h5a.get_num_attrs(self._id)
  File "h5py/_objects.pyx", line 54, in h5py._objects.with_phil.wrapper
  File "h5py/_objects.pyx", line 55, in h5py._objects.with_phil.wrapper
  File "h5py/h5a.pyx", line 159, in h5py.h5a.get_num_attrs
ValueError: Invalid location identifier (invalid identifier type to function)
Traceback (most recent call last):
  File "/home/zimmer/.local/lib/python3.9/site-packages/IPython/core/completer.py", line 2159, in _complete
    for m in matcher(text)])
  File "/home/zimmer/.local/lib/python3.9/site-packages/IPython/core/completer.py", line 1713, in dict_key_matches
    keys = self._get_keys(obj)
  File "/home/zimmer/.local/lib/python3.9/site-packages/IPython/core/completer.py", line 1643, in _get_keys
    return method()
  File "/home/zimmer/.conda/envs/neutrino_clustering/lib/python3.9/site-packages/h5py/_hl/base.py", line 467, in _ipython_key_completions_
    return sorted(self.keys())
  File "/home/zimmer/.conda/envs/neutrino_clustering/lib/python3.9/_collections_abc.py", line 805, in __len__
    return len(self._mapping)
  File "h5py/_objects.pyx", line 54, in h5py._objects.with_phil.wrapper
  File "h5py/_objects.pyx", line 55, in h5py._objects.with_phil.wrapper
  File "/home/zimmer/.conda/envs/neutrino_clustering/lib/python3.9/site-packages/h5py/_hl/attrs.py", line 254, in __len__
    return h5a.get_num_attrs(self._id)
  File "h5py/_objects.pyx", line 54, in h5py._objects.with_phil.wrapper
  File "h5py/_objects.pyx", line 55, in h5py._objects.with_phil.wrapper
  File "h5py/h5a.pyx", line 159, in h5py.h5a.get_num_attrs
ValueError: Invalid location identifier (invalid identifier type to function)
Traceback (most recent call last):
  File "/home/zimmer/.local/lib/python3.9/site-packages/IPython/core/completer.py", line 2159, in _complete
    for m in matcher(text)])
  File "/home/zimmer/.local/lib/python3.9/site-packages/IPython/core/completer.py", line 1713, in dict_key_matches
    keys = self._get_keys(obj)
  File "/home/zimmer/.local/lib/python3.9/site-packages/IPython/core/completer.py", line 1643, in _get_keys
    return method()
  File "/home/zimmer/.conda/envs/neutrino_clustering/lib/python3.9/site-packages/h5py/_hl/base.py", line 467, in _ipython_key_completions_
    return sorted(self.keys())
  File "/home/zimmer/.conda/envs/neutrino_clustering/lib/python3.9/_collections_abc.py", line 805, in __len__
    return len(self._mapping)
  File "h5py/_objects.pyx", line 54, in h5py._objects.with_phil.wrapper
  File "h5py/_objects.pyx", line 55, in h5py._objects.with_phil.wrapper
  File "/home/zimmer/.conda/envs/neutrino_clustering/lib/python3.9/site-packages/h5py/_hl/attrs.py", line 254, in __len__
    return h5a.get_num_attrs(self._id)
  File "h5py/_objects.pyx", line 54, in h5py._objects.with_phil.wrapper
  File "h5py/_objects.pyx", line 55, in h5py._objects.with_phil.wrapper
  File "h5py/h5a.pyx", line 159, in h5py.h5a.get_num_attrs
ValueError: Invalid location identifier (invalid identifier type to function)
Traceback (most recent call last):
  File "/home/zimmer/.local/lib/python3.9/site-packages/IPython/core/completer.py", line 2159, in _complete
    for m in matcher(text)])
  File "/home/zimmer/.local/lib/python3.9/site-packages/IPython/core/completer.py", line 1713, in dict_key_matches
    keys = self._get_keys(obj)
  File "/home/zimmer/.local/lib/python3.9/site-packages/IPython/core/completer.py", line 1643, in _get_keys
    return method()
  File "/home/zimmer/.conda/envs/neutrino_clustering/lib/python3.9/site-packages/h5py/_hl/base.py", line 467, in _ipython_key_completions_
    return sorted(self.keys())
  File "/home/zimmer/.conda/envs/neutrino_clustering/lib/python3.9/_collections_abc.py", line 805, in __len__
    return len(self._mapping)
  File "h5py/_objects.pyx", line 54, in h5py._objects.with_phil.wrapper
  File "h5py/_objects.pyx", line 55, in h5py._objects.with_phil.wrapper
  File "/home/zimmer/.conda/envs/neutrino_clustering/lib/python3.9/site-packages/h5py/_hl/attrs.py", line 254, in __len__
    return h5a.get_num_attrs(self._id)
  File "h5py/_objects.pyx", line 54, in h5py._objects.with_phil.wrapper
  File "h5py/_objects.pyx", line 55, in h5py._objects.with_phil.wrapper
  File "h5py/h5a.pyx", line 159, in h5py.h5a.get_num_attrs
ValueError: Invalid location identifier (invalid identifier type to function)
Traceback (most recent call last):
  File "/home/zimmer/.local/lib/python3.9/site-packages/IPython/core/completer.py", line 2159, in _complete
    for m in matcher(text)])
  File "/home/zimmer/.local/lib/python3.9/site-packages/IPython/core/completer.py", line 1713, in dict_key_matches
    keys = self._get_keys(obj)
  File "/home/zimmer/.local/lib/python3.9/site-packages/IPython/core/completer.py", line 1643, in _get_keys
    return method()
  File "/home/zimmer/.conda/envs/neutrino_clustering/lib/python3.9/site-packages/h5py/_hl/base.py", line 467, in _ipython_key_completions_
    return sorted(self.keys())
  File "/home/zimmer/.conda/envs/neutrino_clustering/lib/python3.9/_collections_abc.py", line 805, in __len__
    return len(self._mapping)
  File "h5py/_objects.pyx", line 54, in h5py._objects.with_phil.wrapper
  File "h5py/_objects.pyx", line 55, in h5py._objects.with_phil.wrapper
  File "/home/zimmer/.conda/envs/neutrino_clustering/lib/python3.9/site-packages/h5py/_hl/attrs.py", line 254, in __len__
    return h5a.get_num_attrs(self._id)
  File "h5py/_objects.pyx", line 54, in h5py._objects.with_phil.wrapper
  File "h5py/_objects.pyx", line 55, in h5py._objects.with_phil.wrapper
  File "h5py/h5a.pyx", line 159, in h5py.h5a.get_num_attrs
ValueError: Invalid location identifier (invalid identifier type to function)
Traceback (most recent call last):
  File "/home/zimmer/.local/lib/python3.9/site-packages/IPython/core/completer.py", line 2159, in _complete
    for m in matcher(text)])
  File "/home/zimmer/.local/lib/python3.9/site-packages/IPython/core/completer.py", line 1713, in dict_key_matches
    keys = self._get_keys(obj)
  File "/home/zimmer/.local/lib/python3.9/site-packages/IPython/core/completer.py", line 1643, in _get_keys
    return method()
  File "/home/zimmer/.conda/envs/neutrino_clustering/lib/python3.9/site-packages/h5py/_hl/base.py", line 467, in _ipython_key_completions_
    return sorted(self.keys())
  File "/home/zimmer/.conda/envs/neutrino_clustering/lib/python3.9/_collections_abc.py", line 805, in __len__
    return len(self._mapping)
  File "h5py/_objects.pyx", line 54, in h5py._objects.with_phil.wrapper
  File "h5py/_objects.pyx", line 55, in h5py._objects.with_phil.wrapper
  File "/home/zimmer/.conda/envs/neutrino_clustering/lib/python3.9/site-packages/h5py/_hl/attrs.py", line 254, in __len__
    return h5a.get_num_attrs(self._id)
  File "h5py/_objects.pyx", line 54, in h5py._objects.with_phil.wrapper
  File "h5py/_objects.pyx", line 55, in h5py._objects.with_phil.wrapper
  File "h5py/h5a.pyx", line 159, in h5py.h5a.get_num_attrs
ValueError: Invalid location identifier (invalid identifier type to function)
Traceback (most recent call last):
  File "/home/zimmer/.local/lib/python3.9/site-packages/IPython/core/completer.py", line 2159, in _complete
    for m in matcher(text)])
  File "/home/zimmer/.local/lib/python3.9/site-packages/IPython/core/completer.py", line 1713, in dict_key_matches
    keys = self._get_keys(obj)
  File "/home/zimmer/.local/lib/python3.9/site-packages/IPython/core/completer.py", line 1643, in _get_keys
    return method()
  File "/home/zimmer/.conda/envs/neutrino_clustering/lib/python3.9/site-packages/h5py/_hl/base.py", line 467, in _ipython_key_completions_
    return sorted(self.keys())
  File "/home/zimmer/.conda/envs/neutrino_clustering/lib/python3.9/_collections_abc.py", line 805, in __len__
    return len(self._mapping)
  File "h5py/_objects.pyx", line 54, in h5py._objects.with_phil.wrapper
  File "h5py/_objects.pyx", line 55, in h5py._objects.with_phil.wrapper
  File "/home/zimmer/.conda/envs/neutrino_clustering/lib/python3.9/site-packages/h5py/_hl/attrs.py", line 254, in __len__
    return h5a.get_num_attrs(self._id)
  File "h5py/_objects.pyx", line 54, in h5py._objects.with_phil.wrapper
  File "h5py/_objects.pyx", line 55, in h5py._objects.with_phil.wrapper
  File "h5py/h5a.pyx", line 159, in h5py.h5a.get_num_attrs
ValueError: Invalid location identifier (invalid identifier type to function)
Traceback (most recent call last):
  File "/home/zimmer/.local/lib/python3.9/site-packages/IPython/core/completer.py", line 2159, in _complete
    for m in matcher(text)])
  File "/home/zimmer/.local/lib/python3.9/site-packages/IPython/core/completer.py", line 1713, in dict_key_matches
    keys = self._get_keys(obj)
  File "/home/zimmer/.local/lib/python3.9/site-packages/IPython/core/completer.py", line 1643, in _get_keys
    return method()
  File "/home/zimmer/.conda/envs/neutrino_clustering/lib/python3.9/site-packages/h5py/_hl/base.py", line 467, in _ipython_key_completions_
    return sorted(self.keys())
  File "/home/zimmer/.conda/envs/neutrino_clustering/lib/python3.9/_collections_abc.py", line 805, in __len__
    return len(self._mapping)
  File "h5py/_objects.pyx", line 54, in h5py._objects.with_phil.wrapper
  File "h5py/_objects.pyx", line 55, in h5py._objects.with_phil.wrapper
  File "/home/zimmer/.conda/envs/neutrino_clustering/lib/python3.9/site-packages/h5py/_hl/attrs.py", line 254, in __len__
    return h5a.get_num_attrs(self._id)
  File "h5py/_objects.pyx", line 54, in h5py._objects.with_phil.wrapper
  File "h5py/_objects.pyx", line 55, in h5py._objects.with_phil.wrapper
  File "h5py/h5a.pyx", line 159, in h5py.h5a.get_num_attrs
ValueError: Invalid location identifier (invalid identifier type to function)
