Exception in thread Thread-599:
Traceback (most recent call last):
  File "/home/zimmer/.conda/envs/neutrino_clustering/lib/python3.9/threading.py", line 954, in _bootstrap_inner
    self.run()
  File "/home/zimmer/.conda/envs/neutrino_clustering/lib/python3.9/concurrent/futures/process.py", line 317, in run
    result_item, is_broken, cause = self.wait_result_broken_or_wakeup()
  File "/home/zimmer/.conda/envs/neutrino_clustering/lib/python3.9/concurrent/futures/process.py", line 376, in wait_result_broken_or_wakeup
    worker_sentinels = [p.sentinel for p in self.processes.values()]
  File "/home/zimmer/.conda/envs/neutrino_clustering/lib/python3.9/concurrent/futures/process.py", line 376, in <listcomp>
    worker_sentinels = [p.sentinel for p in self.processes.values()]
RuntimeError: dictionary changed size during iteration
slurmstepd: error: *** JOB 2673496 ON tcn263 CANCELLED AT 2023-04-29T17:55:32 DUE TO TIME LIMIT ***
